[2025-02-13T04:21:42.020+0000] {local_task_job_runner.py:120} INFO - ::group::Pre task execution logs
[2025-02-13T04:21:42.052+0000] {taskinstance.py:2073} INFO - Dependencies all met for dep_context=non-requeueable deps ti=<TaskInstance: DAG_INETUM_ETL.load_data_task manual__2025-02-13T04:21:20.465557+00:00 [queued]>
[2025-02-13T04:21:42.067+0000] {taskinstance.py:2073} INFO - Dependencies all met for dep_context=requeueable deps ti=<TaskInstance: DAG_INETUM_ETL.load_data_task manual__2025-02-13T04:21:20.465557+00:00 [queued]>
[2025-02-13T04:21:42.068+0000] {taskinstance.py:2303} INFO - Starting attempt 1 of 2
[2025-02-13T04:21:42.095+0000] {taskinstance.py:2327} INFO - Executing <Task(PythonOperator): load_data_task> on 2025-02-13 04:21:20.465557+00:00
[2025-02-13T04:21:42.110+0000] {warnings.py:110} WARNING - /home/***/.local/lib/python3.12/site-packages/***/task/task_runner/standard_task_runner.py:61: DeprecationWarning: This process (pid=4156) is multi-threaded, use of fork() may lead to deadlocks in the child.
  pid = os.fork()

[2025-02-13T04:21:42.114+0000] {standard_task_runner.py:63} INFO - Started process 4165 to run task
[2025-02-13T04:21:42.114+0000] {standard_task_runner.py:90} INFO - Running: ['***', 'tasks', 'run', 'DAG_INETUM_ETL', 'load_data_task', 'manual__2025-02-13T04:21:20.465557+00:00', '--job-id', '58', '--raw', '--subdir', 'DAGS_FOLDER/dag_etl.py', '--cfg-path', '/tmp/tmpsgpp4f_o']
[2025-02-13T04:21:42.118+0000] {standard_task_runner.py:91} INFO - Job 58: Subtask load_data_task
[2025-02-13T04:21:42.228+0000] {task_command.py:426} INFO - Running <TaskInstance: DAG_INETUM_ETL.load_data_task manual__2025-02-13T04:21:20.465557+00:00 [running]> on host 9a237c96c334
[2025-02-13T04:21:42.444+0000] {taskinstance.py:2644} INFO - Exporting env vars: AIRFLOW_CTX_DAG_OWNER='Andres Urrea' AIRFLOW_CTX_DAG_ID='DAG_INETUM_ETL' AIRFLOW_CTX_TASK_ID='load_data_task' AIRFLOW_CTX_EXECUTION_DATE='2025-02-13T04:21:20.465557+00:00' AIRFLOW_CTX_TRY_NUMBER='1' AIRFLOW_CTX_DAG_RUN_ID='manual__2025-02-13T04:21:20.465557+00:00'
[2025-02-13T04:21:42.447+0000] {taskinstance.py:430} INFO - ::endgroup::
[2025-02-13T04:21:42.468+0000] {base.py:84} INFO - Using connection ID 'aws_default' for task execution.
[2025-02-13T04:21:42.470+0000] {connection_wrapper.py:384} INFO - AWS Connection (conn_id='aws_default', conn_type='aws') credentials retrieved from login and password.
[2025-02-13T04:21:45.620+0000] {dag_etl.py:88} INFO - Proceso de almacenamiento en la nube se realizado con exito, Archivo /tmp/archivo.json subido a S3 en s3://source-data-spacenews/raw/archivo.json
[2025-02-13T04:21:45.624+0000] {python.py:237} INFO - Done. Returned value was: None
[2025-02-13T04:21:45.626+0000] {taskinstance.py:441} INFO - ::group::Post task execution logs
[2025-02-13T04:21:45.645+0000] {taskinstance.py:1205} INFO - Marking task as SUCCESS. dag_id=DAG_INETUM_ETL, task_id=load_data_task, execution_date=20250213T042120, start_date=20250213T042142, end_date=20250213T042145
[2025-02-13T04:21:45.707+0000] {local_task_job_runner.py:240} INFO - Task exited with return code 0
[2025-02-13T04:21:45.772+0000] {taskinstance.py:3482} INFO - 1 downstream tasks scheduled from follow-on schedule check
[2025-02-13T04:21:45.776+0000] {local_task_job_runner.py:222} INFO - ::endgroup::
