[2025-02-11T19:29:19.515+0000] {local_task_job_runner.py:120} INFO - ::group::Pre task execution logs
[2025-02-11T19:29:19.561+0000] {taskinstance.py:2073} INFO - Dependencies all met for dep_context=non-requeueable deps ti=<TaskInstance: DAG_INETUM_ETL.load_data_task manual__2025-02-11T19:28:56.889101+00:00 [queued]>
[2025-02-11T19:29:19.582+0000] {taskinstance.py:2073} INFO - Dependencies all met for dep_context=requeueable deps ti=<TaskInstance: DAG_INETUM_ETL.load_data_task manual__2025-02-11T19:28:56.889101+00:00 [queued]>
[2025-02-11T19:29:19.586+0000] {taskinstance.py:2303} INFO - Starting attempt 1 of 2
[2025-02-11T19:29:19.625+0000] {taskinstance.py:2327} INFO - Executing <Task(PythonOperator): load_data_task> on 2025-02-11 19:28:56.889101+00:00
[2025-02-11T19:29:19.642+0000] {warnings.py:110} WARNING - /home/***/.local/lib/python3.12/site-packages/***/task/task_runner/standard_task_runner.py:61: DeprecationWarning: This process (pid=4496) is multi-threaded, use of fork() may lead to deadlocks in the child.
  pid = os.fork()

[2025-02-11T19:29:19.647+0000] {standard_task_runner.py:63} INFO - Started process 4498 to run task
[2025-02-11T19:29:19.648+0000] {standard_task_runner.py:90} INFO - Running: ['***', 'tasks', 'run', 'DAG_INETUM_ETL', 'load_data_task', 'manual__2025-02-11T19:28:56.889101+00:00', '--job-id', '37', '--raw', '--subdir', 'DAGS_FOLDER/dag_etl.py', '--cfg-path', '/tmp/tmpq4bv5hj1']
[2025-02-11T19:29:19.653+0000] {standard_task_runner.py:91} INFO - Job 37: Subtask load_data_task
[2025-02-11T19:29:19.774+0000] {task_command.py:426} INFO - Running <TaskInstance: DAG_INETUM_ETL.load_data_task manual__2025-02-11T19:28:56.889101+00:00 [running]> on host 9a237c96c334
[2025-02-11T19:29:20.071+0000] {taskinstance.py:2644} INFO - Exporting env vars: AIRFLOW_CTX_DAG_OWNER='Andres Urrea' AIRFLOW_CTX_DAG_ID='DAG_INETUM_ETL' AIRFLOW_CTX_TASK_ID='load_data_task' AIRFLOW_CTX_EXECUTION_DATE='2025-02-11T19:28:56.889101+00:00' AIRFLOW_CTX_TRY_NUMBER='1' AIRFLOW_CTX_DAG_RUN_ID='manual__2025-02-11T19:28:56.889101+00:00'
[2025-02-11T19:29:20.075+0000] {taskinstance.py:430} INFO - ::endgroup::
[2025-02-11T19:29:20.106+0000] {base.py:84} INFO - Using connection ID 'aws_default' for task execution.
[2025-02-11T19:29:20.108+0000] {connection_wrapper.py:384} INFO - AWS Connection (conn_id='aws_default', conn_type='aws') credentials retrieved from login and password.
[2025-02-11T19:29:23.532+0000] {dag_etl.py:88} INFO - Proceso de almacenamiento en la nube se realizado con exito, Archivo /tmp/archivo.json subido a S3 en s3://source-data-spacenews/raw/archivo.json
[2025-02-11T19:29:23.535+0000] {python.py:237} INFO - Done. Returned value was: None
[2025-02-11T19:29:23.537+0000] {taskinstance.py:441} INFO - ::group::Post task execution logs
[2025-02-11T19:29:23.559+0000] {taskinstance.py:1205} INFO - Marking task as SUCCESS. dag_id=DAG_INETUM_ETL, task_id=load_data_task, execution_date=20250211T192856, start_date=20250211T192919, end_date=20250211T192923
[2025-02-11T19:29:23.643+0000] {local_task_job_runner.py:240} INFO - Task exited with return code 0
[2025-02-11T19:29:23.721+0000] {taskinstance.py:3482} INFO - 1 downstream tasks scheduled from follow-on schedule check
[2025-02-11T19:29:23.726+0000] {local_task_job_runner.py:222} INFO - ::endgroup::
