[2025-02-11T17:08:07.443+0000] {local_task_job_runner.py:120} INFO - ::group::Pre task execution logs
[2025-02-11T17:08:07.496+0000] {taskinstance.py:2073} INFO - Dependencies all met for dep_context=non-requeueable deps ti=<TaskInstance: DAG_INETUM_ETL.run_glue_crawler manual__2025-02-11T17:08:00.921612+00:00 [queued]>
[2025-02-11T17:08:07.515+0000] {taskinstance.py:2073} INFO - Dependencies all met for dep_context=requeueable deps ti=<TaskInstance: DAG_INETUM_ETL.run_glue_crawler manual__2025-02-11T17:08:00.921612+00:00 [queued]>
[2025-02-11T17:08:07.517+0000] {taskinstance.py:2303} INFO - Starting attempt 1 of 2
[2025-02-11T17:08:07.550+0000] {taskinstance.py:2327} INFO - Executing <Task(GlueCrawlerOperator): run_glue_crawler> on 2025-02-11 17:08:00.921612+00:00
[2025-02-11T17:08:07.573+0000] {warnings.py:110} WARNING - /home/***/.local/lib/python3.12/site-packages/***/task/task_runner/standard_task_runner.py:61: DeprecationWarning: This process (pid=2755) is multi-threaded, use of fork() may lead to deadlocks in the child.
  pid = os.fork()

[2025-02-11T17:08:07.577+0000] {standard_task_runner.py:63} INFO - Started process 2762 to run task
[2025-02-11T17:08:07.577+0000] {standard_task_runner.py:90} INFO - Running: ['***', 'tasks', 'run', 'DAG_INETUM_ETL', 'run_glue_crawler', 'manual__2025-02-11T17:08:00.921612+00:00', '--job-id', '19', '--raw', '--subdir', 'DAGS_FOLDER/dag_etl.py', '--cfg-path', '/tmp/tmp5cznby98']
[2025-02-11T17:08:07.581+0000] {standard_task_runner.py:91} INFO - Job 19: Subtask run_glue_crawler
[2025-02-11T17:08:07.759+0000] {task_command.py:426} INFO - Running <TaskInstance: DAG_INETUM_ETL.run_glue_crawler manual__2025-02-11T17:08:00.921612+00:00 [running]> on host 9a237c96c334
[2025-02-11T17:08:08.188+0000] {taskinstance.py:2644} INFO - Exporting env vars: AIRFLOW_CTX_DAG_OWNER='Andres Urrea' AIRFLOW_CTX_DAG_ID='DAG_INETUM_ETL' AIRFLOW_CTX_TASK_ID='run_glue_crawler' AIRFLOW_CTX_EXECUTION_DATE='2025-02-11T17:08:00.921612+00:00' AIRFLOW_CTX_TRY_NUMBER='1' AIRFLOW_CTX_DAG_RUN_ID='manual__2025-02-11T17:08:00.921612+00:00'
[2025-02-11T17:08:08.191+0000] {taskinstance.py:430} INFO - ::endgroup::
[2025-02-11T17:08:08.192+0000] {glue_crawler.py:57} INFO - Checking if crawler already exists: crawler-oregon-source-s3
[2025-02-11T17:08:08.214+0000] {base.py:84} INFO - Using connection ID 'aws_default' for task execution.
[2025-02-11T17:08:08.219+0000] {connection_wrapper.py:384} INFO - AWS Connection (conn_id='aws_default', conn_type='aws') credentials retrieved from login and password.
[2025-02-11T17:08:10.939+0000] {glue_crawler.py:98} INFO - Triggering AWS Glue Crawler
[2025-02-11T17:08:10.940+0000] {glue_crawler.py:170} INFO - Starting crawler crawler-oregon-source-s3
[2025-02-11T17:08:11.208+0000] {taskinstance.py:441} INFO - ::group::Post task execution logs
[2025-02-11T17:08:11.210+0000] {taskinstance.py:2890} ERROR - Task failed with exception
Traceback (most recent call last):
  File "/home/airflow/.local/lib/python3.12/site-packages/airflow/models/taskinstance.py", line 465, in _execute_task
    result = _execute_callable(context=context, **execute_callable_kwargs)
             ^^^^^^^^^^^^^^^^^^^^^^^^^^^^^^^^^^^^^^^^^^^^^^^^^^^^^^^^^^^^^
  File "/home/airflow/.local/lib/python3.12/site-packages/airflow/models/taskinstance.py", line 432, in _execute_callable
    return execute_callable(context=context, **execute_callable_kwargs)
           ^^^^^^^^^^^^^^^^^^^^^^^^^^^^^^^^^^^^^^^^^^^^^^^^^^^^^^^^^^^^
  File "/home/airflow/.local/lib/python3.12/site-packages/airflow/models/baseoperator.py", line 400, in wrapper
    return func(self, *args, **kwargs)
           ^^^^^^^^^^^^^^^^^^^^^^^^^^^
  File "/home/airflow/.local/lib/python3.12/site-packages/airflow/providers/amazon/aws/operators/glue_crawler.py", line 99, in execute
    self.hook.start_crawler(crawler_name)
  File "/home/airflow/.local/lib/python3.12/site-packages/airflow/providers/amazon/aws/hooks/glue_crawler.py", line 171, in start_crawler
    return self.glue_client.start_crawler(Name=crawler_name)
           ^^^^^^^^^^^^^^^^^^^^^^^^^^^^^^^^^^^^^^^^^^^^^^^^^
  File "/home/airflow/.local/lib/python3.12/site-packages/botocore/client.py", line 553, in _api_call
    return self._make_api_call(operation_name, kwargs)
           ^^^^^^^^^^^^^^^^^^^^^^^^^^^^^^^^^^^^^^^^^^^
  File "/home/airflow/.local/lib/python3.12/site-packages/botocore/client.py", line 1009, in _make_api_call
    raise error_class(parsed_response, operation_name)
botocore.errorfactory.CrawlerRunningException: An error occurred (CrawlerRunningException) when calling the StartCrawler operation: Crawler with name crawler-oregon-source-s3 has already started
[2025-02-11T17:08:11.271+0000] {taskinstance.py:1205} INFO - Marking task as UP_FOR_RETRY. dag_id=DAG_INETUM_ETL, task_id=run_glue_crawler, execution_date=20250211T170800, start_date=20250211T170807, end_date=20250211T170811
[2025-02-11T17:08:11.312+0000] {standard_task_runner.py:110} ERROR - Failed to execute job 19 for task run_glue_crawler (An error occurred (CrawlerRunningException) when calling the StartCrawler operation: Crawler with name crawler-oregon-source-s3 has already started; 2762)
[2025-02-11T17:08:11.382+0000] {local_task_job_runner.py:240} INFO - Task exited with return code 1
[2025-02-11T17:08:11.462+0000] {taskinstance.py:3482} INFO - 0 downstream tasks scheduled from follow-on schedule check
[2025-02-11T17:08:11.469+0000] {local_task_job_runner.py:222} INFO - ::endgroup::
